<?xml version="1.0"?>

<robot name="head_base_frame" xmlns:xacro="http://www.ros.org/wiki/xacro">

  <xacro:include filename="$(find pir2_description)/urdf/head/head.transmission.xacro"/>
  <xacro:include filename="$(find pir2_description)/urdf/head/head.gazebo.xacro"/>

  <xacro:macro name="head_frame" params="parent angle">

    <xacro:property name="yaw_angle" value="${-angle}"/>

    <joint name="pan_support_joint" type="fixed">
      <origin xyz="0 0 0.0015 " rpy="0 0 0" />
      <parent link="${parent}"/>
      <child link="pan_support_link"/>
    </joint>

    <link name="pan_support_link" >
      <visual>
        <origin xyz="0 0 0" rpy="0 0 0" />
        <geometry>
          <mesh filename="package://pir2_description/meshes/head/pan_support.stl" scale="0.001 0.001 0.001"/>
        </geometry>
        <material name="grey"/>
      </visual>
    </link>

    <joint name="head_base_joint" type="fixed">
      <origin xyz="0 0 0.0316 " rpy="0 0 0" />
      <parent link="${parent}"/>
      <child link="head_base_link"/>
    </joint>

    <link name="head_base_link" >
      <visual>
        <origin xyz="0 0 0" rpy="0 0 0" />
        <geometry>
          <!--box size="0.07 0.085 0.065" /-->
          <mesh filename="package://pir2_description/meshes/head/pan_frame.stl" scale="0.001 0.001 0.001"/>
        </geometry>
        <material name="grey"/>
      </visual>
      <collision>
        <origin xyz="-0.015 0 0" rpy="0 0 0"/>
        <geometry>
           <box size="0.06 0.06 0.05"/>
        </geometry>
      </collision>
     <inertial>
       <origin xyz="-0.015 0 0" rpy="0 0 0"/>
       <mass value="0.02"/>
       <inertia
  	    ixx="0.0001" ixy="0.0" ixz="0.0"
  	    iyy="0.00012" iyz="0.0"
  	    izz="0.0001"/>
     </inertial>
    </link>

    <joint name="pan_joint" type="revolute">
      <parent link="head_base_link"/>
      <child link="pan_link"/>
      <origin xyz="0 0 0.0245" rpy="0 0 0" />
      <axis xyz="0 0 1" />
      <limit lower="-1.3" upper="1.3" effort="10" velocity="1"/>
      <dynamics damping="0.7"/>
    </joint>


    <link name="pan_link" >
      <visual>
        <origin xyz="0 0 0.0515" rpy="0 0 0" />
        <geometry>
          <!--box size="0.07 0.085 0.065" /-->
          <mesh filename="package://pir2_description/meshes/head/tilt_frame.stl" scale="0.001 0.001 0.001"/>
        </geometry>
        <material name="grey"/>
      </visual>
      <collision>
        <origin xyz="0 0 0.018" rpy="0 0 0"/>
        <geometry>
          <box size="0.04 0.04 0.03"/>
        </geometry>
      </collision>
      <inertial>
        <origin xyz="0 0 0.018" rpy="0 0 0"/>
        <mass value="0.03"/>
        <inertia
          ixx="0.0000625" ixy="0.0" ixz="0.0"
          iyy="0.00008" iyz="0.0"
          izz="0.0000625"/>
      </inertial>
    </link>

    <joint name="tilt_joint" type="revolute">
      <parent link="pan_link"/>
      <child link="tilt_link"/>
      <origin xyz="0 0.0245 0.0515" rpy="-1.57 -1.57 0" />
      <axis xyz="0 0 1" />
      <limit lower="-0.3490658503988659" upper="0.17453292519943295" effort="10" velocity="1"/>
      <dynamics damping="0.7"/>
    </joint>


    <link name="tilt_link" >
      <visual>
        <origin xyz="0 0 -0.0245" rpy="0 0 0" />
        <geometry>
          <mesh filename="package://pir2_description/meshes/head/yaw_plate.stl" scale="0.001 0.001 0.001"/>
        </geometry>
        <material name="grey"/>
      </visual>
      <collision>
        <origin xyz="0.035 0 -0.025" rpy="0 0 0"/>
        <geometry>
          <box size="0.004 0.18 0.06"/>
        </geometry>
      </collision>
      <inertial>
        <origin xyz="0.035 0 -0.025" rpy="0 0 0"/>
        <mass value="0.04"/>
        <inertia
          ixx="0.032" ixy="0.0" ixz="0.0"
          iyy="0.0010" iyz="0.0"
          izz="0.0012"/>
      </inertial>
    </link>

    <joint name="yaw_plate_to_dxl_joint" type="fixed">
      <origin xyz="0.0233 0.1 -0.0245" rpy="1.57 0 ${yaw_angle+1.57}" />
      <parent link="tilt_link"/>
      <child link="yaw_dxl_link"/>
    </joint>

    <link name="yaw_dxl_link" >
      <visual>
        <origin xyz="0.027 0 0" rpy="0 0 0" />
        <geometry>
          <mesh filename="package://pir2_description/meshes/head/yaw_frame.stl" scale="0.001 0.001 0.001"/>
        </geometry>
        <material name="grey"/>
      </visual>
      <collision>
        <origin xyz="-0.013 0 -0.015" rpy="0 0 0"/>
        <geometry>
          <box size="0.035 0.053 0.054"/>
        </geometry>
      </collision>
      <inertial>
        <origin xyz="-0.013 0 -0.015" rpy="0 0 0"/>
        <mass value="0.02"/>
        <inertia
         ixx="0.0028" ixy="0.0" ixz="0.0"
         iyy="0.0012" iyz="0.0"
         izz="0.0012"/>
      </inertial>
    </link>

    <joint name="yaw_joint" type="revolute">
      <parent link="yaw_dxl_link"/>
      <child link="yaw_link"/>
      <origin xyz="0.0515 0 0" rpy="0 -1.57 3.14" />
      <axis xyz="0 0 1" />
      <limit lower="-1.3" upper="1.3" effort="10" velocity="1"/>
      <dynamics damping="0.7"/>
    </joint>

    <link name="yaw_link" >
      <visual>
        <origin xyz="0 0 0" rpy="0 0 0" />
        <geometry>
          <!--box size="0.07 0.085 0.065" /-->
          <mesh filename="package://pir2_description/meshes/head/display_frame.stl" scale="0.001 0.001 0.001"/>
        </geometry>
        <material name="grey"/>
      </visual>
      <collision>
        <origin xyz="0 0 0" rpy="0 0 0"/>
        <geometry>
          <box size="0.16 0.26 0.004"/>
        </geometry>
      </collision>
      <inertial>
        <origin xyz="0 0 0" rpy="0 0 0"/>
        <mass value="0.01"/>
        <inertia
          ixx="0.00057" ixy="0.0" ixz="0.0"
          iyy="0.00077" iyz="0.0"
          izz="0.025"/>
       </inertial>
    </link>

  </xacro:macro>

</robot>
