<?xml version="1.0" ?>
<robot name="pir2_wheel" xmlns:xacro="http://ros.org/wiki/xacro">
  <xacro:include filename="$(find pir2_description)/urdf/wheels/wheel.gazebo.xacro"/>

  <xacro:macro name="wheel" params="parent" >
    <joint name="wheel_left_joint" type="continuous">
      <parent link="base_link"/>
      <child link="wheel_left_link"/>
      <origin xyz="0.0 0.26 0.023" rpy="-1.57 0 0"/>
      <axis xyz="0 0 1"/>
    </joint>

    <link name="wheel_left_link">
      <visual>
        <origin xyz="0 0 0" rpy="0 0 0"/>
        <geometry>
          <mesh filename="package://pir2_description/meshes/wheels/left_wheel2.stl" scale="0.001 0.001 0.001"/>
        </geometry>
        <material name="dark"/>
      </visual>

      <collision>
        <origin xyz="0 0 0" rpy="0 0 0"/>
        <geometry>
          <cylinder length="0.018" radius="0.108"/>
        </geometry>
      </collision>

      <inertial>
        <origin xyz="0 0 0" />
        <mass value="0.22" />
        <inertia ixx="0.0011" ixy="0" ixz="0"
                 iyy="0.0011" iyz="0"
                 izz="0.0017" />
        </inertial>

    </link>

    <joint name="wheel_right_joint" type="continuous">
      <parent link="base_link"/>
      <child link="wheel_right_link"/>
      <origin xyz="0.0 -0.26 0.023" rpy="-1.57 0 0"/>
      <axis xyz="0 0 1"/>
    </joint>

    <link name="wheel_right_link">
      <visual>
        <origin xyz="0 0 0" rpy="0 0 0"/>
        <geometry>
          <mesh filename="package://pir2_description/meshes/wheels/right_wheel2.stl" scale="0.001 0.001 0.001"/>
        </geometry>
        <material name="dark"/>
      </visual>

      <collision>
        <origin xyz="0 0 0" rpy="0 0 0"/>
        <geometry>
          <cylinder length="0.018" radius="0.108"/>
        </geometry>
      </collision>

      <inertial>
        <origin xyz="0 0 0" />
        <mass value="0.22" />
        <inertia ixx="0.0011" ixy="0" ixz="0"
                 iyy="0.0011" iyz="0"
                 izz="0.0017" />
        </inertial>
    </link>
  </xacro:macro>

</robot>
